Traceback (most recent call last):
  File "C:\Users\vania wrenda\AppData\Local\Programs\Python\Python312\Lib\site-packages\jupyter_cache\executors\utils.py", line 58, in single_nb_execution
    executenb(
  File "C:\Users\vania wrenda\AppData\Local\Programs\Python\Python312\Lib\site-packages\nbclient\client.py", line 1314, in execute
    return NotebookClient(nb=nb, resources=resources, km=km, **kwargs).execute()
           ^^^^^^^^^^^^^^^^^^^^^^^^^^^^^^^^^^^^^^^^^^^^^^^^^^^^^^^^^^^^^^^^^^^^^
  File "C:\Users\vania wrenda\AppData\Local\Programs\Python\Python312\Lib\site-packages\jupyter_core\utils\__init__.py", line 165, in wrapped
    return loop.run_until_complete(inner)
           ^^^^^^^^^^^^^^^^^^^^^^^^^^^^^^
  File "C:\Users\vania wrenda\AppData\Local\Programs\Python\Python312\Lib\asyncio\base_events.py", line 684, in run_until_complete
    return future.result()
           ^^^^^^^^^^^^^^^
  File "C:\Users\vania wrenda\AppData\Local\Programs\Python\Python312\Lib\site-packages\nbclient\client.py", line 709, in async_execute
    await self.async_execute_cell(
  File "C:\Users\vania wrenda\AppData\Local\Programs\Python\Python312\Lib\site-packages\nbclient\client.py", line 1062, in async_execute_cell
    await self._check_raise_for_error(cell, cell_index, exec_reply)
  File "C:\Users\vania wrenda\AppData\Local\Programs\Python\Python312\Lib\site-packages\nbclient\client.py", line 918, in _check_raise_for_error
    raise CellExecutionError.from_cell_and_msg(cell, exec_reply_content)
nbclient.exceptions.CellExecutionError: An error occurred while executing the following cell:
------------------
# Mengatur fitur (X) dan target (y)
X = df_normalized[['Open', 'High', 'Low', 'Close']]
y = df_normalized['Close Target']

# Membagi data menjadi training dan testing (60% training, 40% testing)
X_train, X_test, y_train, y_test = train_test_split(X, y, test_size=0.4, shuffle=False)
------------------


[1;31m---------------------------------------------------------------------------[0m
[1;31mNameError[0m                                 Traceback (most recent call last)
Cell [1;32mIn[12], line 6[0m
[0;32m      3[0m y [38;5;241m=[39m df_normalized[[38;5;124m'[39m[38;5;124mClose Target[39m[38;5;124m'[39m]
[0;32m      5[0m [38;5;66;03m# Membagi data menjadi training dan testing (60% training, 40% testing)[39;00m
[1;32m----> 6[0m X_train, X_test, y_train, y_test [38;5;241m=[39m [43mtrain_test_split[49m(X, y, test_size[38;5;241m=[39m[38;5;241m0.4[39m, shuffle[38;5;241m=[39m[38;5;28;01mFalse[39;00m)

[1;31mNameError[0m: name 'train_test_split' is not defined

